Workbook

Sheet Dashboard
B1: SALES PERFORMANCE DASHBOARD
B2: ="Rolling 12 months: "&TEXT(Calc!B4,"mmm yyyy")&" – "&TEXT(EDATE(Calc!B4,11),"mmm yyyy")&" | Region: "&C4 -> Rolling 12 months: Oct 2025 – Sep 2026 | Region: All
B4: Region ▸ | C4: All | F4: Pick a region in the yellow cell – KPIs, the monthly chart and the category mix update.
B6: REVENUE | D6: GROSS PROFIT | F6: PROFIT MARGIN | H6: ORDERS | J6: AVG ORDER VALUE | L6: VS TARGET
B7: =SUM(Calc!B8:B19) -> 1421593.1 | D7: =SUM(Calc!C8:C19) -> 806835.73 | F7: =IFERROR(SUM(Calc!C8:C19)/SUM(Calc!B8:B19),0) -> 0.56755744 | H7: =SUM(Calc!D8:D19) -> 374 | J7: =IFERROR(SUM(Calc!B8:B19)/SUM(Calc!D8:D19),0) -> 3801.051 | L7: =IFERROR(SUM(Calc!B8:B19)/SUM(Calc!F8:F19),0) -> 0.96183564
B8: =IF(Calc!B19>=Calc!B18,"▲ ","▼ ")&TEXT(ABS(IFERROR(Calc!B19/Calc!B18-1,0)),"0.0%")&" vs prior month" -> ▲ 20.6% vs prior month | D8: =IF(Calc!C19>=Calc!C18,"▲ ","▼ ")&TEXT(ABS(IFERROR(Calc!C19/Calc!C18-1,0)),"0.0%")&" vs prior month" -> ▲ 19.0% vs prior month | F8: ="Last month: "&TEXT(Calc!G19,"0.0%") -> Last month: 56.1% | H8: =IF(Calc!D19>=Calc!D18,"▲ ","▼ ")&TEXT(ABS(IFERROR(Calc!D19/Calc!D18-1,0)),"0.0%")&" vs prior month" -> ▲ 14.3% vs prior month | J8: ="Last month: "&TEXT(IFERROR(Calc!B19/Calc!D19,0),"$#,##0") -> Last month: $3,768 | L8: ="Target: "&TEXT(SUM(Calc!F8:F19),"$#,##0") -> Target: $1,478,000
B10: TRENDS & MIX
B43: LEADERBOARD & REGIONS
B44: # | C44: Sales rep | D44: Region | E44: Revenue | F44: Target | G44: Attainment | I44: Region | J44: Revenue | K44: Profit | L44: Margin | M44: vs target
B45: =Calc!A50 -> 1 | C45: =Calc!B50 -> Sofia Rossi | D45: =Calc!C50 -> North | E45: =Calc!D50 -> 212231.3 | F45: =Calc!E50 -> 212000 | G45: =Calc!F50 -> 1.001091 | I45: =Calc!A23 -> North | J45: =Calc!B23 -> 374637.07 | K45: =Calc!C23 -> 214734.51 | L45: =Calc!D23 -> 0.57318009 | M45: =Calc!F23 -> 0.93193301
B46: =Calc!A51 -> 2 | C46: =Calc!B51 -> Noah Becker | D46: =Calc!C51 -> West | E46: =Calc!D51 -> 207557.45 | F46: =Calc!E51 -> 219000 | G46: =Calc!F51 -> 0.94775091 | I46: =Calc!A24 -> South | J46: =Calc!B24 -> 352969.96 | K46: =Calc!C24 -> 201394.93 | L46: =Calc!D24 -> 0.57057244 | M46: =Calc!F24 -> 0.94125323
B47: =Calc!A52 -> 3 | C47: =Calc!B52 -> Elena Petrova | D47: =Calc!C52 -> South | E47: =Calc!D52 -> 180039.3 | F47: =Calc!E52 -> 197000 | G47: =Calc!F52 -> 0.91390508 | I47: =Calc!A25 -> East | J47: =Calc!B25 -> 309096.52 | K47: =Calc!C25 -> 172410.77 | L47: =Calc!D25 -> 0.55778942 | M47: =Calc!F25 -> 1.0658501
B48: =Calc!A53 -> 4 | C48: =Calc!B53 -> Maya Lopez | D48: =Calc!C53 -> West | E48: =Calc!D53 -> 177332.08 | F48: =Calc!E53 -> 183000 | G48: =Calc!F53 -> 0.96902776 | I48: =Calc!A26 -> West | J48: =Calc!B26 -> 384889.53 | K48: =Calc!C26 -> 218295.52 | L48: =Calc!D26 -> 0.56716409 | M48: =Calc!F26 -> 0.93647088
B49: =Calc!A54 -> 5 | C49: =Calc!B54 -> Omar Haddad | D49: =Calc!C54 -> South | E49: =Calc!D54 -> 172930.66 | F49: =Calc!E54 -> 167000 | G49: =Calc!F54 -> 1.0355129 | I49: =Calc!A27 -> Total | J49: =Calc!B27 -> 1421593.1 | K49: =Calc!C27 -> 806835.73 | L49: =Calc!D27 -> 0.56755744 | M49: =Calc!F27 -> 0.96183564
B50: =Calc!A55 -> 6 | C50: =Calc!B55 -> Priya Nair | D50: =Calc!C55 -> East | E50: =Calc!D55 -> 171053.24 | F50: =Calc!E55 -> 186000 | G50: =Calc!F55 -> 0.91964108
B51: =Calc!A56 -> 7 | C51: =Calc!B56 -> Liam Carter | D51: =Calc!C56 -> North | E51: =Calc!D56 -> 162405.77 | F51: =Calc!E56 -> 160000 | G51: =Calc!F56 -> 1.0150361
B52: =Calc!A57 -> 8 | C52: =Calc!B57 -> Kenji Tanaka | D52: =Calc!C57 -> East | E52: =Calc!D57 -> 138043.28 | F52: =Calc!E57 -> 142000 | G52: =Calc!F57 -> 0.97213577
B54: Region filter drives the KPI cards, monthly chart and category mix. The region view and rep leaderboard always show every region/rep. Attainment colours: green ≥ 100%, amber 90–99%, red < 90%.

Sheet Data
A1: Date | B1: Order ID | C1: Region | D1: Sales Rep | E1: Category | F1: Units | G1: Unit Price ($) | H1: Unit Cost ($) | I1: Revenue ($) | J1: Profit ($)
A2: 45933 | B2: SO-1001 | C2: East | D2: Kenji Tanaka | E2: Accessories | F2: 34 | G2: 61.39 | H2: 34.99 | I2: =F2*G2 -> 2087.26 | J2: =I2-F2*H2 -> 897.6
A3: 45933 | B3: SO-1002 | C3: North | D3: Liam Carter | E3: Accessories | F3: 64 | G3: 26.46 | H3: 14.06 | I3: =F3*G3 -> 1693.44 | J3: =I3-F3*H3 -> 793.6
A4: 45934 | B4: SO-1003 | C4: North | D4: Sofia Rossi | E4: Services | F4: 9 | G4: 164.3 | H4: 70.93 | I4: =F4*G4 -> 1478.7 | J4: =I4-F4*H4 -> 840.33
A5: 45934 | B5: SO-1004 | C5: North | D5: Sofia Rossi | E5: Software | F5: 21 | G5: 158.98 | H5: 34.43 | I5: =F5*G5 -> 3338.58 | J5: =I5-F5*H5 -> 2615.55
A6: 45935 | B6: SO-1005 | C6: South | D6: Elena Petrova | E6: Services | F6: 15 | G6: 392.54 | H6: 181.01 | I6: =F6*G6 -> 5888.1 | J6: =I6-F6*H6 -> 3172.95
A7: 45936 | B7: SO-1006 | C7: East | D7: Priya Nair | E7: Software | F7: 9 | G7: 227.44 | H7: 51.05 | I7: =F7*G7 -> 2046.96 | J7: =I7-F7*H7 -> 1587.51
A8: 45937 | B8: SO-1007 | C8: West | D8: Maya Lopez | E8: Software | F8: 21 | G8: 281.2 | H8: 61.61 | I8: =F8*G8 -> 5905.2 | J8: =I8-F8*H8 -> 4611.39
A9: 45938 | B9: SO-1008 | C9: West | D9: Maya Lopez | E9: Services | F9: 7 | G9: 514.24 | H9: 219.99 | I9: =F9*G9 -> 3599.68 | J9: =I9-F9*H9 -> 2059.75
A10: 45947 | B10: SO-1009 | C10: North | D10: Liam Carter | E10: Services | F10: 15 | G10: 472.21 | H10: 216.77 | I10: =F10*G10 -> 7083.15 | J10: =I10-F10*H10 -> 3831.6
A11: 45948 | B11: SO-1010 | C11: North | D11: Liam Carter | E11: Services | F11: 10 | G11: 201.55 | H11: 94.19 | I11: =F11*G11 -> 2015.5 | J11: =I11-F11*H11 -> 1073.6
A12: 45949 | B12: SO-1011 | C12: West | D12: Noah Becker | E12: Software | F12: 36 | G12: 299.41 | H12: 63.49 | I12: =F12*G12 -> 10778.76 | J12: =I12-F12*H12 -> 8493.12
A13: 45950 | B13: SO-1012 | C13: South | D13: Omar Haddad | E13: Software | F13: 22 | G13: 133.86 | H13: 29.34 | I13: =F13*G13 -> 2944.92 | J13: =I13-F13*H13 -> 2299.44
... A375: 46293 | B375: SO-1374 | C375: North | D375: Liam Carter | E375: Hardware | F375: 9 | G375: 278.75 | H375: 188.39 | I375: =F375*G375 -> 2508.75 | J375: =I375-F375*H375 -> 813.24

Sheet Calc
A1: Calculation layer (feeds the Dashboard – no need to edit except the blue/yellow inputs)
A2: Region filter (from Dashboard) | B2: =Dashboard!C4 -> All
A3: Region criterion | B3: =IF(B2="All","*",B2) -> *
A4: Period start (first month) | B4: 45931
A5: Period end (exclusive) | B5: =EDATE(B4,12) -> 46296
A7: Month | B7: Revenue | C7: Profit | D7: Orders | E7: Units | F7: Target | G7: Margin | H7: Label
A8: =$B$4 -> 45931 | B8: =SUMIFS(Data!$I$2:$I$2000,Data!$A$2:$A$2000,">="&$A8,Data!$A$2:$A$2000,"<"&EDATE($A8,1),Data!$C$2:$C$2000,$B$3) -> 91979.87 | C8: =SUMIFS(Data!$J$2:$J$2000,Data!$A$2:$A$2000,">="&$A8,Data!$A$2:$A$2000,"<"&EDATE($A8,1),Data!$C$2:$C$2000,$B$3) -> 54829.27 | D8: =COUNTIFS(Data!$A$2:$A$2000,">="&$A8,Data!$A$2:$A$2000,"<"&EDATE($A8,1),Data!$C$2:$C$2000,$B$3) -> 25 | E8: =SUMIFS(Data!$F$2:$F$2000,Data!$A$2:$A$2000,">="&$A8,Data!$A$2:$A$2000,"<"&EDATE($A8,1),Data!$C$2:$C$2000,$B$3) -> 574 | F8: =IF($B$2="All",SUM($E$23:$E$26),INDEX($E$23:$E$26,MATCH($B$2,$A$23:$A$26,0)))/12 -> 123166.67 | G8: =IFERROR(C8/B8,0) -> 0.59610076 | H8: =TEXT(A8,"mmm yy") -> Oct 25
A9: =EDATE(A8,1) -> 45962 | B9: =SUMIFS(Data!$I$2:$I$2000,Data!$A$2:$A$2000,">="&$A9,Data!$A$2:$A$2000,"<"&EDATE($A9,1),Data!$C$2:$C$2000,$B$3) -> 100542.15 | C9: =SUMIFS(Data!$J$2:$J$2000,Data!$A$2:$A$2000,">="&$A9,Data!$A$2:$A$2000,"<"&EDATE($A9,1),Data!$C$2:$C$2000,$B$3) -> 55745.01 | D9: =COUNTIFS(Data!$A$2:$A$2000,">="&$A9,Data!$A$2:$A$2000,"<"&EDATE($A9,1),Data!$C$2:$C$2000,$B$3) -> 28 | E9: =SUMIFS(Data!$F$2:$F$2000,Data!$A$2:$A$2000,">="&$A9,Data!$A$2:$A$2000,"<"&EDATE($A9,1),Data!$C$2:$C$2000,$B$3) -> 499 | F9: =IF($B$2="All",SUM($E$23:$E$26),INDEX($E$23:$E$26,MATCH($B$2,$A$23:$A$26,0)))/12 -> 123166.67 | G9: =IFERROR(C9/B9,0) -> 0.55444418 | H9: =TEXT(A9,"mmm yy") -> Nov 25
A10: =EDATE(A9,1) -> 45992 | B10: =SUMIFS(Data!$I$2:$I$2000,Data!$A$2:$A$2000,">="&$A10,Data!$A$2:$A$2000,"<"&EDATE($A10,1),Data!$C$2:$C$2000,$B$3) -> 126462.1 | C10: =SUMIFS(Data!$J$2:$J$2000,Data!$A$2:$A$2000,">="&$A10,Data!$A$2:$A$2000,"<"&EDATE($A10,1),Data!$C$2:$C$2000,$B$3) -> 76841.78 | D10: =COUNTIFS(Data!$A$2:$A$2000,">="&$A10,Data!$A$2:$A$2000,"<"&EDATE($A10,1),Data!$C$2:$C$2000,$B$3) -> 34 | E10: =SUMIFS(Data!$F$2:$F$2000,Data!$A$2:$A$2000,">="&$A10,Data!$A$2:$A$2000,"<"&EDATE($A10,1),Data!$C$2:$C$2000,$B$3) -> 852 | F10: =IF($B$2="All",SUM($E$23:$E$26),INDEX($E$23:$E$26,MATCH($B$2,$A$23:$A$26,0)))/12 -> 123166.67 | G10: =IFERROR(C10/B10,0) -> 0.60762695 | H10: =TEXT(A10,"mmm yy") -> Dec 25
A11: =EDATE(A10,1) -> 46023 | B11: =SUMIFS(Data!$I$2:$I$2000,Data!$A$2:$A$2000,">="&$A11,Data!$A$2:$A$2000,"<"&EDATE($A11,1),Data!$C$2:$C$2000,$B$3) -> 92891.84 | C11: =SUMIFS(Data!$J$2:$J$2000,Data!$A$2:$A$2000,">="&$A11,Data!$A$2:$A$2000,"<"&EDATE($A11,1),Data!$C$2:$C$2000,$B$3) -> 54410.87 | D11: =COUNTIFS(Data!$A$2:$A$2000,">="&$A11,Data!$A$2:$A$2000,"<"&EDATE($A11,1),Data!$C$2:$C$2000,$B$3) -> 23 | E11: =SUMIFS(Data!$F$2:$F$2000,Data!$A$2:$A$2000,">="&$A11,Data!$A$2:$A$2000,"<"&EDATE($A11,1),Data!$C$2:$C$2000,$B$3) -> 511 | F11: =IF($B$2="All",SUM($E$23:$E$26),INDEX($E$23:$E$26,MATCH($B$2,$A$23:$A$26,0)))/12 -> 123166.67 | G11: =IFERROR(C11/B11,0) -> 0.58574435 | H11: =TEXT(A11,"mmm yy") -> Jan 26
A12: =EDATE(A11,1) -> 46054 | B12: =SUMIFS(Data!$I$2:$I$2000,Data!$A$2:$A$2000,">="&$A12,Data!$A$2:$A$2000,"<"&EDATE($A12,1),Data!$C$2:$C$2000,$B$3) -> 95290.06 | C12: =SUMIFS(Data!$J$2:$J$2000,Data!$A$2:$A$2000,">="&$A12,Data!$A$2:$A$2000,"<"&EDATE($A12,1),Data!$C$2:$C$2000,$B$3) -> 56558.41 | D12: =COUNTIFS(Data!$A$2:$A$2000,">="&$A12,Data!$A$2:$A$2000,"<"&EDATE($A12,1),Data!$C$2:$C$2000,$B$3) -> 25 | E12: =SUMIFS(Data!$F$2:$F$2000,Data!$A$2:$A$2000,">="&$A12,Data!$A$2:$A$2000,"<"&EDATE($A12,1),Data!$C$2:$C$2000,$B$3) -> 518 | F12: =IF($B$2="All",SUM($E$23:$E$26),INDEX($E$23:$E$26,MATCH($B$2,$A$23:$A$26,0)))/12 -> 123166.67 | G12: =IFERROR(C12/B12,0) -> 0.59353945 | H12: =TEXT(A12,"mmm yy") -> Feb 26
A13: =EDATE(A12,1) -> 46082 | B13: =SUMIFS(Data!$I$2:$I$2000,Data!$A$2:$A$2000,">="&$A13,Data!$A$2:$A$2000,"<"&EDATE($A13,1),Data!$C$2:$C$2000,$B$3) -> 136010.5 | C13: =SUMIFS(Data!$J$2:$J$2000,Data!$A$2:$A$2000,">="&$A13,Data!$A$2:$A$2000,"<"&EDATE($A13,1),Data!$C$2:$C$2000,$B$3) -> 82435.78 | D13: =COUNTIFS(Data!$A$2:$A$2000,">="&$A13,Data!$A$2:$A$2000,"<"&EDATE($A13,1),Data!$C$2:$C$2000,$B$3) -> 29 | E13: =SUMIFS(Data!$F$2:$F$2000,Data!$A$2:$A$2000,">="&$A13,Data!$A$2:$A$2000,"<"&EDATE($A13,1),Data!$C$2:$C$2000,$B$3) -> 521 | F13: =IF($B$2="All",SUM($E$23:$E$26),INDEX($E$23:$E$26,MATCH($B$2,$A$23:$A$26,0)))/12 -> 123166.67 | G13: =IFERROR(C13/B13,0) -> 0.60609865 | H13: =TEXT(A13,"mmm yy") -> Mar 26
A14: =EDATE(A13,1) -> 46113 | B14: =SUMIFS(Data!$I$2:$I$2000,Data!$A$2:$A$2000,">="&$A14,Data!$A$2:$A$2000,"<"&EDATE($A14,1),Data!$C$2:$C$2000,$B$3) -> 109432.34 | C14: =SUMIFS(Data!$J$2:$J$2000,Data!$A$2:$A$2000,">="&$A14,Data!$A$2:$A$2000,"<"&EDATE($A14,1),Data!$C$2:$C$2000,$B$3) -> 51388.06 | D14: =COUNTIFS(Data!$A$2:$A$2000,">="&$A14,Data!$A$2:$A$2000,"<"&EDATE($A14,1),Data!$C$2:$C$2000,$B$3) -> 31 | E14: =SUMIFS(Data!$F$2:$F$2000,Data!$A$2:$A$2000,">="&$A14,Data!$A$2:$A$2000,"<"&EDATE($A14,1),Data!$C$2:$C$2000,$B$3) -> 625 | F14: =IF($B$2="All",SUM($E$23:$E$26),INDEX($E$23:$E$26,MATCH($B$2,$A$23:$A$26,0)))/12 -> 123166.67 | G14: =IFERROR(C14/B14,0) -> 0.46958751 | H14: =TEXT(A14,"mmm yy") -> Apr 26
A15: =EDATE(A14,1) -> 46143 | B15: =SUMIFS(Data!$I$2:$I$2000,Data!$A$2:$A$2000,">="&$A15,Data!$A$2:$A$2000,"<"&EDATE($A15,1),Data!$C$2:$C$2000,$B$3) -> 127692.69 | C15: =SUMIFS(Data!$J$2:$J$2000,Data!$A$2:$A$2000,">="&$A15,Data!$A$2:$A$2000,"<"&EDATE($A15,1),Data!$C$2:$C$2000,$B$3) -> 72501.14 | D15: =COUNTIFS(Data!$A$2:$A$2000,">="&$A15,Data!$A$2:$A$2000,"<"&EDATE($A15,1),Data!$C$2:$C$2000,$B$3) -> 33 | E15: =SUMIFS(Data!$F$2:$F$2000,Data!$A$2:$A$2000,">="&$A15,Data!$A$2:$A$2000,"<"&EDATE($A15,1),Data!$C$2:$C$2000,$B$3) -> 681 | F15: =IF($B$2="All",SUM($E$23:$E$26),INDEX($E$23:$E$26,MATCH($B$2,$A$23:$A$26,0)))/12 -> 123166.67 | G15: =IFERROR(C15/B15,0) -> 0.56777831 | H15: =TEXT(A15,"mmm yy") -> May 26
A16: =EDATE(A15,1) -> 46174 | B16: =SUMIFS(Data!$I$2:$I$2000,Data!$A$2:$A$2000,">="&$A16,Data!$A$2:$A$2000,"<"&EDATE($A16,1),Data!$C$2:$C$2000,$B$3) -> 133109.52 | C16: =SUMIFS(Data!$J$2:$J$2000,Data!$A$2:$A$2000,">="&$A16,Data!$A$2:$A$2000,"<"&EDATE($A16,1),Data!$C$2:$C$2000,$B$3) -> 70943.6 | D16: =COUNTIFS(Data!$A$2:$A$2000,">="&$A16,Data!$A$2:$A$2000,"<"&EDATE($A16,1),Data!$C$2:$C$2000,$B$3) -> 35 | E16: =SUMIFS(Data!$F$2:$F$2000,Data!$A$2:$A$2000,">="&$A16,Data!$A$2:$A$2000,"<"&EDATE($A16,1),Data!$C$2:$C$2000,$B$3) -> 616 | F16: =IF($B$2="All",SUM($E$23:$E$26),INDEX($E$23:$E$26,MATCH($B$2,$A$23:$A$26,0)))/12 -> 123166.67 | G16: =IFERROR(C16/B16,0) -> 0.53297165 | H16: =TEXT(A16,"mmm yy") -> Jun 26
A17: =EDATE(A16,1) -> 46204 | B17: =SUMIFS(Data!$I$2:$I$2000,Data!$A$2:$A$2000,">="&$A17,Data!$A$2:$A$2000,"<"&EDATE($A17,1),Data!$C$2:$C$2000,$B$3) -> 132471.72 | C17: =SUMIFS(Data!$J$2:$J$2000,Data!$A$2:$A$2000,">="&$A17,Data!$A$2:$A$2000,"<"&EDATE($A17,1),Data!$C$2:$C$2000,$B$3) -> 75510.72 | D17: =COUNTIFS(Data!$A$2:$A$2000,">="&$A17,Data!$A$2:$A$2000,"<"&EDATE($A17,1),Data!$C$2:$C$2000,$B$3) -> 36 | E17: =SUMIFS(Data!$F$2:$F$2000,Data!$A$2:$A$2000,">="&$A17,Data!$A$2:$A$2000,"<"&EDATE($A17,1),Data!$C$2:$C$2000,$B$3) -> 721 | F17: =IF($B$2="All",SUM($E$23:$E$26),INDEX($E$23:$E$26,MATCH($B$2,$A$23:$A$26,0)))/12 -> 123166.67 | G17: =IFERROR(C17/B17,0) -> 0.57001389 | H17: =TEXT(A17,"mmm yy") -> Jul 26
A18: =EDATE(A17,1) -> 46235 | B18: =SUMIFS(Data!$I$2:$I$2000,Data!$A$2:$A$2000,">="&$A18,Data!$A$2:$A$2000,"<"&EDATE($A18,1),Data!$C$2:$C$2000,$B$3) -> 125008.86 | C18: =SUMIFS(Data!$J$2:$J$2000,Data!$A$2:$A$2000,">="&$A18,Data!$A$2:$A$2000,"<"&EDATE($A18,1),Data!$C$2:$C$2000,$B$3) -> 71066.6 | D18: =COUNTIFS(Data!$A$2:$A$2000,">="&$A18,Data!$A$2:$A$2000,"<"&EDATE($A18,1),Data!$C$2:$C$2000,$B$3) -> 35 | E18: =SUMIFS(Data!$F$2:$F$2000,Data!$A$2:$A$2000,">="&$A18,Data!$A$2:$A$2000,"<"&EDATE($A18,1),Data!$C$2:$C$2000,$B$3) -> 731 | F18: =IF($B$2="All",SUM($E$23:$E$26),INDEX($E$23:$E$26,MATCH($B$2,$A$23:$A$26,0)))/12 -> 123166.67 | G18: =IFERROR(C18/B18,0) -> 0.56849251 | H18: =TEXT(A18,"mmm yy") -> Aug 26
A19: =EDATE(A18,1) -> 46266 | B19: =SUMIFS(Data!$I$2:$I$2000,Data!$A$2:$A$2000,">="&$A19,Data!$A$2:$A$2000,"<"&EDATE($A19,1),Data!$C$2:$C$2000,$B$3) -> 150701.43 | C19: =SUMIFS(Data!$J$2:$J$2000,Data!$A$2:$A$2000,">="&$A19,Data!$A$2:$A$2000,"<"&EDATE($A19,1),Data!$C$2:$C$2000,$B$3) -> 84604.49 | D19: =COUNTIFS(Data!$A$2:$A$2000,">="&$A19,Data!$A$2:$A$2000,"<"&EDATE($A19,1),Data!$C$2:$C$2000,$B$3) -> 40 | E19: =SUMIFS(Data!$F$2:$F$2000,Data!$A$2:$A$2000,">="&$A19,Data!$A$2:$A$2000,"<"&EDATE($A19,1),Data!$C$2:$C$2000,$B$3) -> 764 | F19: =IF($B$2="All",SUM($E$23:$E$26),INDEX($E$23:$E$26,MATCH($B$2,$A$23:$A$26,0)))/12 -> 123166.67 | G19: =IFERROR(C19/B19,0) -> 0.56140469 | H19: =TEXT(A19,"mmm yy") -> Sep 26
A22: Region | B22: Revenue | C22: Profit | D22: Margin | E22: Annual target | F22: Attainment
A23: North | B23: =SUMIFS(Data!$I$2:$I$2000,Data!$A$2:$A$2000,">="&$B$4,Data!$A$2:$A$2000,"<"&$B$5,Data!$C$2:$C$2000,$A23) -> 374637.07 | C23: =SUMIFS(Data!$J$2:$J$2000,Data!$A$2:$A$2000,">="&$B$4,Data!$A$2:$A$2000,"<"&$B$5,Data!$C$2:$C$2000,$A23) -> 214734.51 | D23: =IFERROR(C23/B23,0) -> 0.57318009 | E23: 402000 | F23: =IFERROR(B23/E23,0) -> 0.93193301
A24: South | B24: =SUMIFS(Data!$I$2:$I$2000,Data!$A$2:$A$2000,">="&$B$4,Data!$A$2:$A$2000,"<"&$B$5,Data!$C$2:$C$2000,$A24) -> 352969.96 | C24: =SUMIFS(Data!$J$2:$J$2000,Data!$A$2:$A$2000,">="&$B$4,Data!$A$2:$A$2000,"<"&$B$5,Data!$C$2:$C$2000,$A24) -> 201394.93 | D24: =IFERROR(C24/B24,0) -> 0.57057244 | E24: 375000 | F24: =IFERROR(B24/E24,0) -> 0.94125323
A25: East | B25: =SUMIFS(Data!$I$2:$I$2000,Data!$A$2:$A$2000,">="&$B$4,Data!$A$2:$A$2000,"<"&$B$5,Data!$C$2:$C$2000,$A25) -> 309096.52 | C25: =SUMIFS(Data!$J$2:$J$2000,Data!$A$2:$A$2000,">="&$B$4,Data!$A$2:$A$2000,"<"&$B$5,Data!$C$2:$C$2000,$A25) -> 172410.77 | D25: =IFERROR(C25/B25,0) -> 0.55778942 | E25: 290000 | F25: =IFERROR(B25/E25,0) -> 1.0658501
A26: West | B26: =SUMIFS(Data!$I$2:$I$2000,Data!$A$2:$A$2000,">="&$B$4,Data!$A$2:$A$2000,"<"&$B$5,Data!$C$2:$C$2000,$A26) -> 384889.53 | C26: =SUMIFS(Data!$J$2:$J$2000,Data!$A$2:$A$2000,">="&$B$4,Data!$A$2:$A$2000,"<"&$B$5,Data!$C$2:$C$2000,$A26) -> 218295.52 | D26: =IFERROR(C26/B26,0) -> 0.56716409 | E26: 411000 | F26: =IFERROR(B26/E26,0) -> 0.93647088
A27: Total | B27: =SUM(B23:B26) -> 1421593.1 | C27: =SUM(C23:C26) -> 806835.73 | D27: =IFERROR(C27/B27,0) -> 0.56755744 | E27: =SUM(E23:E26) -> 1478000 | F27: =IFERROR(B27/E27,0) -> 0.96183564
A30: Category | B30: Revenue | C30: Profit | D30: Share
A31: Hardware | B31: =SUMIFS(Data!$I$2:$I$2000,Data!$A$2:$A$2000,">="&$B$4,Data!$A$2:$A$2000,"<"&$B$5,Data!$E$2:$E$2000,$A31,Data!$C$2:$C$2000,$B$3) -> 302676.57 | C31: =SUMIFS(Data!$J$2:$J$2000,Data!$A$2:$A$2000,">="&$B$4,Data!$A$2:$A$2000,"<"&$B$5,Data!$E$2:$E$2000,$A31,Data!$C$2:$C$2000,$B$3) -> 96697.23 | D31: =IFERROR(B31/B$35,0) -> 0.21291365
A32: Software | B32: =SUMIFS(Data!$I$2:$I$2000,Data!$A$2:$A$2000,">="&$B$4,Data!$A$2:$A$2000,"<"&$B$5,Data!$E$2:$E$2000,$A32,Data!$C$2:$C$2000,$B$3) -> 482659.94 | C32: =SUMIFS(Data!$J$2:$J$2000,Data!$A$2:$A$2000,">="&$B$4,Data!$A$2:$A$2000,"<"&$B$5,Data!$E$2:$E$2000,$A32,Data!$C$2:$C$2000,$B$3) -> 376548.46 | D32: =IFERROR(B32/B$35,0) -> 0.33952046
A33: Services | B33: =SUMIFS(Data!$I$2:$I$2000,Data!$A$2:$A$2000,">="&$B$4,Data!$A$2:$A$2000,"<"&$B$5,Data!$E$2:$E$2000,$A33,Data!$C$2:$C$2000,$B$3) -> 479642.05 | C33: =SUMIFS(Data!$J$2:$J$2000,Data!$A$2:$A$2000,">="&$B$4,Data!$A$2:$A$2000,"<"&$B$5,Data!$E$2:$E$2000,$A33,Data!$C$2:$C$2000,$B$3) -> 263338.99 | D33: =IFERROR(B33/B$35,0) -> 0.33739757
A34: Accessories | B34: =SUMIFS(Data!$I$2:$I$2000,Data!$A$2:$A$2000,">="&$B$4,Data!$A$2:$A$2000,"<"&$B$5,Data!$E$2:$E$2000,$A34,Data!$C$2:$C$2000,$B$3) -> 156614.52 | C34: =SUMIFS(Data!$J$2:$J$2000,Data!$A$2:$A$2000,">="&$B$4,Data!$A$2:$A$2000,"<"&$B$5,Data!$E$2:$E$2000,$A34,Data!$C$2:$C$2000,$B$3) -> 70251.05 | D34: =IFERROR(B34/B$35,0) -> 0.11016832
A35: Total | B35: =SUM(B31:B34) -> 1421593.1 | C35: =SUM(C31:C34) -> 806835.73 | D35: =SUM(D31:D34) -> 1
A38: Rep | B38: Region | C38: Revenue | D38: Annual target | E38: Sort key | F38: Rank
A39: Liam Carter | B39: North | C39: =SUMIFS(Data!$I$2:$I$2000,Data!$A$2:$A$2000,">="&$B$4,Data!$A$2:$A$2000,"<"&$B$5,Data!$D$2:$D$2000,$A39) -> 162405.77 | D39: 160000 | E39: =C39+ROW()/1000000 -> 162405.77 | F39: =RANK(E39,$E$39:$E$46) -> 7
A40: Sofia Rossi | B40: North | C40: =SUMIFS(Data!$I$2:$I$2000,Data!$A$2:$A$2000,">="&$B$4,Data!$A$2:$A$2000,"<"&$B$5,Data!$D$2:$D$2000,$A40) -> 212231.3 | D40: 212000 | E40: =C40+ROW()/1000000 -> 212231.3 | F40: =RANK(E40,$E$39:$E$46) -> 1
A41: Omar Haddad | B41: South | C41: =SUMIFS(Data!$I$2:$I$2000,Data!$A$2:$A$2000,">="&$B$4,Data!$A$2:$A$2000,"<"&$B$5,Data!$D$2:$D$2000,$A41) -> 172930.66 | D41: 167000 | E41: =C41+ROW()/1000000 -> 172930.66 | F41: =RANK(E41,$E$39:$E$46) -> 5
A42: Elena Petrova | B42: South | C42: =SUMIFS(Data!$I$2:$I$2000,Data!$A$2:$A$2000,">="&$B$4,Data!$A$2:$A$2000,"<"&$B$5,Data!$D$2:$D$2000,$A42) -> 180039.3 | D42: 197000 | E42: =C42+ROW()/1000000 -> 180039.3 | F42: =RANK(E42,$E$39:$E$46) -> 3
A43: Kenji Tanaka | B43: East | C43: =SUMIFS(Data!$I$2:$I$2000,Data!$A$2:$A$2000,">="&$B$4,Data!$A$2:$A$2000,"<"&$B$5,Data!$D$2:$D$2000,$A43) -> 138043.28 | D43: 142000 | E43: =C43+ROW()/1000000 -> 138043.28 | F43: =RANK(E43,$E$39:$E$46) -> 8
A44: Priya Nair | B44: East | C44: =SUMIFS(Data!$I$2:$I$2000,Data!$A$2:$A$2000,">="&$B$4,Data!$A$2:$A$2000,"<"&$B$5,Data!$D$2:$D$2000,$A44) -> 171053.24 | D44: 186000 | E44: =C44+ROW()/1000000 -> 171053.24 | F44: =RANK(E44,$E$39:$E$46) -> 6
A45: Noah Becker | B45: West | C45: =SUMIFS(Data!$I$2:$I$2000,Data!$A$2:$A$2000,">="&$B$4,Data!$A$2:$A$2000,"<"&$B$5,Data!$D$2:$D$2000,$A45) -> 207557.45 | D45: 219000 | E45: =C45+ROW()/1000000 -> 207557.45 | F45: =RANK(E45,$E$39:$E$46) -> 2
A46: Maya Lopez | B46: West | C46: =SUMIFS(Data!$I$2:$I$2000,Data!$A$2:$A$2000,">="&$B$4,Data!$A$2:$A$2000,"<"&$B$5,Data!$D$2:$D$2000,$A46) -> 177332.08 | D46: 183000 | E46: =C46+ROW()/1000000 -> 177332.08 | F46: =RANK(E46,$E$39:$E$46) -> 4
A49: Rank | B49: Rep | C49: Region | D49: Revenue | E49: Target | F49: Attainment
...

Sheet Guide
B2: HOW TO USE THIS WORKBOOK
B3: 1. Add data | C3: Paste new orders at the bottom of the Data sheet (columns A–H, blue). Copy the Revenue and Profit formulas (I–J) down. Formulas read rows 2–2000.
B4: 2. Roll the period | C4: Change the yellow 'Period start' cell on the Calc sheet (B4). The Dashboard always shows 12 months from that date.
B5: 3. Set targets | C5: Edit the blue annual targets for regions (Calc E23:E26) and reps (Calc D39:D46).
B6: 4. Filter | C6: Use the yellow region dropdown on the Dashboard (C4).
B8: COLOUR CODE
B9: Blue text | C9: Hard-coded input you can change (sample data, targets).
B10: Black text | C10: Formula – do not overwrite.
B11: Yellow fill | C11: Control cell (filter, period start).
B13: ASSUMPTIONS
B14: Sample data | C14: All 300+ orders, prices, costs and targets are synthetic and were generated for illustration. Replace with your own data.
B15: Currency | C15: Shown in $. Change the number formats if you report in another currency (e.g. MAD).
B16: Profit | C16: Profit = Revenue − Units × Unit Cost (gross profit, before overheads).
B18: LAYOUT LOGIC
B19: Top band | C19: Title, period and filter – tells the reader what they are looking at.
B20: KPI row | C20: Six headline numbers, left to right: size (revenue, profit) → quality (margin) → volume (orders, AOV) → goal (vs target).
B21: Chart grid | C21: Trend (top-left) → breakdowns by region/category/rep. Max 4 charts, same size, aligned to the same grid.
B22: Tables | C22: Exact numbers with traffic-light attainment for anyone who wants to drill in.
